<sdf version='1.7'>
  <world name='default'>
    <light name='sun' type='directional'>
      <cast_shadows>1</cast_shadows>
      <pose>0 0 10 0 -0 0</pose>
      <diffuse>0.8 0.8 0.8 1</diffuse>
      <specular>0.2 0.2 0.2 1</specular>
      <attenuation>
        <range>1000</range>
        <constant>0.9</constant>
        <linear>0.01</linear>
        <quadratic>0.001</quadratic>
      </attenuation>
      <direction>-0.5 0.1 -0.9</direction>
      <spot>
        <inner_angle>0</inner_angle>
        <outer_angle>0</outer_angle>
        <falloff>0</falloff>
      </spot>
    </light>
    <model name='ground_plane'>
      <static>1</static>
      <link name='link'>
        <collision name='collision'>
          <geometry>
            <plane>
              <normal>0 0 1</normal>
              <size>100 100</size>
            </plane>
          </geometry>
          <surface>
            <friction>
              <ode>
                <mu>100</mu>
                <mu2>50</mu2>
              </ode>
              <torsional>
                <ode/>
              </torsional>
            </friction>
            <contact>
              <ode/>
            </contact>
            <bounce/>
          </surface>
          <max_contacts>10</max_contacts>
        </collision>
        <visual name='visual'>
          <cast_shadows>0</cast_shadows>
          <geometry>
            <plane>
              <normal>0 0 1</normal>
              <size>100 100</size>
            </plane>
          </geometry>
          <material>
            <script>
              <uri>file://media/materials/scripts/gazebo.material</uri>
              <name>Gazebo/Grey</name>
            </script>
          </material>
        </visual>
        <self_collide>0</self_collide>
        <enable_wind>0</enable_wind>
        <kinematic>0</kinematic>
      </link>
    </model>
    <gravity>0 0 -9.8</gravity>
    <magnetic_field>6e-06 2.3e-05 -4.2e-05</magnetic_field>
    <atmosphere type='adiabatic'/>
    <physics type='ode'>
      <max_step_size>0.001</max_step_size>
      <real_time_factor>1</real_time_factor>
      <real_time_update_rate>1000</real_time_update_rate>
    </physics>
    <scene>
      <ambient>0.4 0.4 0.4 1</ambient>
      <background>0.7 0.7 0.7 1</background>
      <shadows>1</shadows>
    </scene>
    <audio>
      <device>default</device>
    </audio>
    <wind/>
    <spherical_coordinates>
      <surface_model>EARTH_WGS84</surface_model>
      <latitude_deg>0</latitude_deg>
      <longitude_deg>0</longitude_deg>
      <elevation>0</elevation>
      <heading_deg>0</heading_deg>
    </spherical_coordinates>
    <model name='maze'>
      <pose>15.8489 -0.6464 0.4 0 -0 0</pose>
      <static>1</static>
      <link name='link'>
        <collision name='collision'>
          <geometry>
            <mesh>
              <uri>model://maze/meshes/maze_3D.dae</uri>
              <scale>0.01 0.01 0.01</scale>
            </mesh>
          </geometry>
          <max_contacts>10</max_contacts>
          <surface>
            <contact>
              <ode/>
            </contact>
            <bounce/>
            <friction>
              <torsional>
                <ode/>
              </torsional>
              <ode/>
            </friction>
          </surface>
        </collision>
        <visual name='visual'>
          <geometry>
            <mesh>
              <uri>model://maze/meshes/maze_3D.dae</uri>
              <scale>0.01 0.01 0.01</scale>
            </mesh>
          </geometry>
        </visual>
        <self_collide>0</self_collide>
        <enable_wind>0</enable_wind>
        <kinematic>0</kinematic>
      </link>
    </model>
    <state world_name='default'>
      <sim_time>240 571000000</sim_time>
      <real_time>66 580892315</real_time>
      <wall_time>1747257943 109048167</wall_time>
      <iterations>65513</iterations>
      <model name='Evader'>
        <pose>12.498 6.5 0.007826 3.6e-05 0.006699 -3.13961</pose>
        <scale>1 1 1</scale>
        <link name='base_footprint'>
          <pose>12.498 6.5 0.007826 3.6e-05 0.006699 -3.13961</pose>
          <velocity>-3e-06 5.5e-05 -0.093069 0.000203 -0.001937 4.9e-05</velocity>
          <acceleration>-0.00076 -8.7e-05 -0.803319 -0.011198 0.263164 6.3e-05</acceleration>
          <wrench>-0.00076 -8.7e-05 -0.803319 0 -0 0</wrench>
        </link>
        <link name='base_link'>
          <pose>12.498 6.5 0.007826 3.6e-05 0.0067 -3.13961</pose>
          <velocity>-4.7e-05 5.6e-05 -0.093012 0.000206 -0.001724 4.9e-05</velocity>
          <acceleration>0.01194 0.000452 -0.820016 -0.011248 0.263446 2.5e-05</acceleration>
          <wrench>0.016392 0.00062 -1.12581 0 -0 0</wrench>
        </link>
        <link name='base_scan'>
          <pose>12.498 6.5 0.007826 3.6e-05 0.006694 -3.13961</pose>
          <velocity>9e-06 5.6e-05 -0.093093 0.000198 -0.002936 4.9e-05</velocity>
          <acceleration>0.02853 0.00115 -0.816709 -0.011135 0.26384 6.6e-05</acceleration>
          <wrench>0.003252 0.000131 -0.093105 0 -0 0</wrench>
        </link>
        <link name='camera_link'>
          <pose>12.498 6.5 0.007826 3.6e-05 0.006695 -3.13961</pose>
          <velocity>2e-06 5.5e-05 -0.093076 0.0002 -0.002655 4.9e-05</velocity>
          <acceleration>-0.00084 -9.3e-05 -0.803193 -0.011162 0.263763 6.5e-05</acceleration>
          <wrench>-0.00084 -9.3e-05 -0.803193 0 -0 0</wrench>
        </link>
        <link name='camera_rgb_frame'>
          <pose>12.4282 6.54687 0.11436 3.6e-05 0.006695 -3.13961</pose>
          <velocity>-0.000304 2.6e-05 -0.093281 0.000209 -0.002663 4.2e-05</velocity>
          <acceleration>0.055343 0.002271 -0.767388 -0.011175 0.263762 5.9e-05</acceleration>
          <wrench>0.001937 7.9e-05 -0.026859 0 -0 0</wrench>
        </link>
        <link name='caster_back_left_link'>
          <pose>12.6752 6.43635 0.005013 -0.927771 -0.192555 3.08971</pose>
          <velocity>6e-06 6.2e-05 -0.092495 -0.009497 0.003685 -0</velocity>
          <acceleration>-0.000676 0.000543 -0.880052 0 -0 0</acceleration>
          <wrench>-1e-06 1e-06 -0.00088 0 -0 0</wrench>
        </link>
        <link name='caster_back_right_link'>
          <pose>12.6749 6.56435 0.005009 -1.0431 -0.186336 3.1015</pose>
          <velocity>-2e-06 6.2e-05 -0.09247 -0.007577 0.003217 0</velocity>
          <acceleration>-0.000346 0.000484 -0.881404 0 -0 0</acceleration>
          <wrench>-0 0 -0.000881 0 -0 0</wrench>
        </link>
        <link name='imu_link'>
          <pose>12.498 6.5 0.007826 3.6e-05 0.006695 -3.13961</pose>
          <velocity>2e-06 5.5e-05 -0.093077 0.000195 -0.002703 4.9e-05</velocity>
          <acceleration>-0.000776 -8.9e-05 -0.803267 -0.011062 0.262471 6.9e-05</acceleration>
          <wrench>-0.000776 -8.9e-05 -0.803267 0 -0 0</wrench>
        </link>
        <link name='wheel_left_link'>
          <pose>12.499 6.5 0.007855 3.1e-05 0.049438 -3.13957</pose>
          <velocity>-2e-05 1.4e-05 -0.093291 -0.001371 -0.001912 7e-06</velocity>
          <acceleration>0.005396 0.000186 -0.801754 -0.005349 0.163439 0.002843</acceleration>
          <wrench>0.00054 1.9e-05 -0.080175 0 -0 0</wrench>
        </link>
        <link name='wheel_right_link'>
          <pose>12.4997 6.5 0.0079 3.2e-05 0.080641 -3.13955</pose>
          <velocity>-2.3e-05 1.4e-05 -0.092838 -0.001373 -0.002345 5e-06</velocity>
          <acceleration>0.005372 0.000185 -0.804784 -0.005327 0.162714 0.002849</acceleration>
          <wrench>0.000537 1.8e-05 -0.080478 0 -0 0</wrench>
        </link>
      </model>
      <model name='Pursuer'>
        <pose>-0.001995 -0 0.007811 4.9e-05 0.006696 -3.1396</pose>
        <scale>1 1 1</scale>
        <link name='base_footprint'>
          <pose>-0.001995 -0 0.007811 4.9e-05 0.006696 -3.1396</pose>
          <velocity>3.5e-05 5.5e-05 -0.087555 0.000317 -0.003055 5e-05</velocity>
          <acceleration>0.00147 -0.00039 0.960266 -0.012534 -0.301255 -6.7e-05</acceleration>
          <wrench>0.00147 -0.00039 0.960266 0 -0 0</wrench>
        </link>
        <link name='base_link'>
          <pose>-0.001995 -0 0.007811 4.9e-05 0.006697 -3.1396</pose>
          <velocity>-1e-05 5.6e-05 -0.087505 0.000321 -0.002827 4.9e-05</velocity>
          <acceleration>-0.013118 0.000203 0.979503 -0.012591 -0.301327 -9.9e-05</acceleration>
          <wrench>-0.01801 0.000279 1.34477 0 -0 0</wrench>
        </link>
        <link name='base_scan'>
          <pose>-0.001995 -0 0.007811 4.9e-05 0.00669 -3.1396</pose>
          <velocity>4e-05 5.6e-05 -0.087618 0.000305 -0.003895 4.9e-05</velocity>
          <acceleration>-0.032204 0.000983 0.975992 -0.012422 -0.303497 -6.4e-05</acceleration>
          <wrench>-0.003671 0.000112 0.111263 0 -0 0</wrench>
        </link>
        <link name='camera_link'>
          <pose>-0.001995 -0 0.007811 4.9e-05 0.006692 -3.1396</pose>
          <velocity>3.4e-05 5.6e-05 -0.087596 0.000309 -0.003651 4.9e-05</velocity>
          <acceleration>0.00157 -0.000397 0.960426 -0.012461 -0.302964 -6.4e-05</acceleration>
          <wrench>0.00157 -0.000397 0.960426 0 -0 0</wrench>
        </link>
        <link name='camera_rgb_frame'>
          <pose>-0.071803 0.046866 0.114345 4.9e-05 0.006692 -3.1396</pose>
          <velocity>-0.000371 1.3e-05 -0.0879 0.000337 -0.003628 4.3e-05</velocity>
          <acceleration>-0.063045 0.002281 0.91714 -0.012573 -0.303191 -7.5e-05</acceleration>
          <wrench>-0.002207 8e-05 0.0321 0 -0 0</wrench>
        </link>
        <link name='caster_back_left_link'>
          <pose>0.175155 -0.063647 0.004992 -0.926532 -0.191076 3.09078</pose>
          <velocity>1.8e-05 4.9e-05 -0.037104 -0.009784 0.003668 0</velocity>
          <acceleration>-0.000426 -0.0008 0.69268 0.140191 -0.071367 0</acceleration>
          <wrench>-0 -1e-06 0.000693 0 -0 0</wrench>
        </link>
        <link name='caster_back_right_link'>
          <pose>0.1749 0.064353 0.004986 -1.04589 -0.193324 3.0975</pose>
          <velocity>1e-05 3.8e-05 -0.036985 -0.007535 0.002049 -0</velocity>
          <acceleration>-0.000553 -0.00093 0.691405 0.172819 -0.098042 0</acceleration>
          <wrench>-1e-06 -1e-06 0.000691 0 -0 0</wrench>
        </link>
        <link name='imu_link'>
          <pose>-0.001995 -0 0.007811 4.9e-05 0.006692 -3.1396</pose>
          <velocity>2.4e-05 5.6e-05 -0.087606 0.000303 -0.003503 4.9e-05</velocity>
          <acceleration>0.00161 -0.000394 0.96052 -0.012367 -0.303697 -6.1e-05</acceleration>
          <wrench>0.00161 -0.000394 0.96052 0 -0 0</wrench>
        </link>
        <link name='wheel_left_link'>
          <pose>-0.001014 2e-06 0.00784 4.4e-05 0.049566 -3.13956</pose>
          <velocity>-1.2e-05 1.3e-05 -0.087801 -0.001278 -0.001838 -4.5e-05</velocity>
          <acceleration>-0.005787 -5.3e-05 0.962232 0.001312 -0.175268 -0.004049</acceleration>
          <wrench>-0.000579 -5e-06 0.096223 0 -0 0</wrench>
        </link>
        <link name='wheel_right_link'>
          <pose>-0.000282 4e-06 0.007885 4.5e-05 0.080865 -3.13953</pose>
          <velocity>-3e-05 1.3e-05 -0.087339 -0.001299 -0.002272 -4.6e-05</velocity>
          <acceleration>-0.005759 -6.2e-05 0.95848 0.001583 -0.174397 -0.00406</acceleration>
          <wrench>-0.000576 -6e-06 0.095848 0 -0 0</wrench>
        </link>
      </model>
      <model name='ground_plane'>
        <pose>0 0 0 0 -0 0</pose>
        <scale>1 1 1</scale>
        <link name='link'>
          <pose>0 0 0 0 -0 0</pose>
          <velocity>0 0 0 0 -0 0</velocity>
          <acceleration>0 0 0 0 -0 0</acceleration>
          <wrench>0 0 0 0 -0 0</wrench>
        </link>
      </model>
      <model name='maze'>
        <pose>21.1146 1.71806 -0.132208 0 -0 0</pose>
        <scale>1 1 1</scale>
        <link name='link'>
          <pose>21.1146 1.71806 -0.132208 0 -0 0</pose>
          <velocity>0 0 0 0 -0 0</velocity>
          <acceleration>0 0 0 0 -0 0</acceleration>
          <wrench>0 0 0 0 -0 0</wrench>
        </link>
      </model>
      <light name='sun'>
        <pose>0 0 10 0 -0 0</pose>
      </light>
    </state>
    <gui fullscreen='0'>
      <camera name='user_camera'>
        <pose>0.326217 0.293584 13.931 2e-06 1.5618 -1.65583</pose>
        <view_controller>orbit</view_controller>
        <projection_type>perspective</projection_type>
      </camera>
    </gui>
    <model name='Pursuer'>
      <pose>0 0 0.01 0 -0 3.14</pose>
      <link name='base_footprint'>
        <self_collide>0</self_collide>
        <inertial>
          <pose>0 0 0 0 -0 0</pose>
          <inertia>
            <ixx>1</ixx>
            <ixy>0</ixy>
            <ixz>0</ixz>
            <iyy>1</iyy>
            <iyz>0</iyz>
            <izz>1</izz>
          </inertia>
          <mass>1</mass>
        </inertial>
        <enable_wind>0</enable_wind>
        <kinematic>0</kinematic>
      </link>
      <link name='base_link'>
        <inertial>
          <pose>-0.064 0 0.048 0 -0 0</pose>
          <inertia>
            <ixx>0.0421114</ixx>
            <ixy>0</ixy>
            <ixz>0</ixz>
            <iyy>0.0421114</iyy>
            <iyz>0</iyz>
            <izz>0.0752549</izz>
          </inertia>
          <mass>1.37291</mass>
        </inertial>
        <collision name='base_collision'>
          <pose>-0.064 0 0.048 0 -0 0</pose>
          <geometry>
            <box>
              <size>0.265 0.265 0.089</size>
            </box>
          </geometry>
          <max_contacts>10</max_contacts>
          <surface>
            <contact>
              <ode/>
            </contact>
            <bounce/>
            <friction>
              <torsional>
                <ode/>
              </torsional>
              <ode/>
            </friction>
          </surface>
        </collision>
        <visual name='base_visual'>
          <pose>-0.064 0 0 0 -0 0</pose>
          <geometry>
            <mesh>
              <uri>model://turtlebot3_common/meshes/waffle_base.dae</uri>
              <scale>0.001 0.001 0.001</scale>
            </mesh>
          </geometry>
          <material>
            <ambient>0 0 1 1</ambient>
            <diffuse>0 0 1 1</diffuse>
            <specular>0.1 0.1 0.1 1</specular>
          </material>
        </visual>
        <self_collide>0</self_collide>
        <enable_wind>0</enable_wind>
        <kinematic>0</kinematic>
      </link>
      <link name='imu_link'>
        <sensor name='tb3_imu' type='imu'>
          <always_on>1</always_on>
          <update_rate>200</update_rate>
          <imu>
            <angular_velocity>
              <x>
                <noise type='gaussian'>
                  <mean>0</mean>
                  <stddev>0.0002</stddev>
                </noise>
              </x>
              <y>
                <noise type='gaussian'>
                  <mean>0</mean>
                  <stddev>0.0002</stddev>
                </noise>
              </y>
              <z>
                <noise type='gaussian'>
                  <mean>0</mean>
                  <stddev>0.0002</stddev>
                </noise>
              </z>
            </angular_velocity>
            <linear_acceleration>
              <x>
                <noise type='gaussian'>
                  <mean>0</mean>
                  <stddev>0.017</stddev>
                </noise>
              </x>
              <y>
                <noise type='gaussian'>
                  <mean>0</mean>
                  <stddev>0.017</stddev>
                </noise>
              </y>
              <z>
                <noise type='gaussian'>
                  <mean>0</mean>
                  <stddev>0.017</stddev>
                </noise>
              </z>
            </linear_acceleration>
            <angular_velocity/>
            <linear_acceleration/>
          </imu>
          <plugin name='turtlebot3_imu' filename='libgazebo_ros_imu_sensor.so'>
            <ros>
              <remapping>~/out:=imu</remapping>
              <namespace>Pursuer</namespace>
            </ros>
          </plugin>
        </sensor>
        <self_collide>0</self_collide>
        <inertial>
          <pose>0 0 0 0 -0 0</pose>
          <inertia>
            <ixx>1</ixx>
            <ixy>0</ixy>
            <ixz>0</ixz>
            <iyy>1</iyy>
            <iyz>0</iyz>
            <izz>1</izz>
          </inertia>
          <mass>1</mass>
        </inertial>
        <enable_wind>0</enable_wind>
        <kinematic>0</kinematic>
      </link>
      <link name='base_scan'>
        <inertial>
          <pose>-0.052 0 0.111 0 -0 0</pose>
          <inertia>
            <ixx>0.001</ixx>
            <ixy>0</ixy>
            <ixz>0</ixz>
            <iyy>0.001</iyy>
            <iyz>0</iyz>
            <izz>0.001</izz>
          </inertia>
          <mass>0.114</mass>
        </inertial>
        <collision name='lidar_sensor_collision'>
          <pose>-0.052 0 0.111 0 -0 0</pose>
          <geometry>
            <cylinder>
              <radius>0.0508</radius>
              <length>0.055</length>
            </cylinder>
          </geometry>
          <max_contacts>10</max_contacts>
          <surface>
            <contact>
              <ode/>
            </contact>
            <bounce/>
            <friction>
              <torsional>
                <ode/>
              </torsional>
              <ode/>
            </friction>
          </surface>
        </collision>
        <visual name='lidar_sensor_visual'>
          <pose>-0.064 0 0.121 0 -0 0</pose>
          <geometry>
            <mesh>
              <uri>model://turtlebot3_common/meshes/lds.dae</uri>
              <scale>0.001 0.001 0.001</scale>
            </mesh>
          </geometry>
        </visual>
        <sensor name='hls_lfcd_lds' type='ray'>
          <always_on>1</always_on>
          <visualize>1</visualize>
          <pose>-0.064 0 0.121 0 -0 0</pose>
          <update_rate>5</update_rate>
          <ray>
            <scan>
              <horizontal>
                <samples>360</samples>
                <resolution>1</resolution>
                <min_angle>0</min_angle>
                <max_angle>6.28</max_angle>
              </horizontal>
              <vertical>
                <samples>1</samples>
                <min_angle>0</min_angle>
                <max_angle>0</max_angle>
              </vertical>
            </scan>
            <range>
              <min>0.12</min>
              <max>3.5</max>
              <resolution>0.015</resolution>
            </range>
            <noise>
              <type>gaussian</type>
              <mean>0</mean>
              <stddev>0.01</stddev>
            </noise>
          </ray>
          <plugin name='turtlebot3_laserscan' filename='libgazebo_ros_ray_sensor.so'>
            <ros>
              <remapping>~/out:=scan</remapping>
              <namespace>Pursuer</namespace>
            </ros>
            <output_type>sensor_msgs/LaserScan</output_type>
            <frame_name>base_scan</frame_name>
          </plugin>
        </sensor>
        <self_collide>0</self_collide>
        <enable_wind>0</enable_wind>
        <kinematic>0</kinematic>
      </link>
      <link name='wheel_left_link'>
        <inertial>
          <pose>0 0.144 0.023 -1.57 0 0</pose>
          <inertia>
            <ixx>1.11756e-05</ixx>
            <ixy>-4.23698e-11</ixy>
            <ixz>-5.93817e-09</ixz>
            <iyy>1.11924e-05</iyy>
            <iyz>-1.44001e-11</iyz>
            <izz>2.07126e-05</izz>
          </inertia>
          <mass>0.1</mass>
        </inertial>
        <collision name='wheel_left_collision'>
          <pose>0 0.144 0.023 -1.57 0 0</pose>
          <geometry>
            <cylinder>
              <radius>0.033</radius>
              <length>0.018</length>
            </cylinder>
          </geometry>
          <surface>
            <friction>
              <ode>
                <mu>100000</mu>
                <mu2>100000</mu2>
                <fdir1>0 0 0</fdir1>
                <slip1>0</slip1>
                <slip2>0</slip2>
              </ode>
              <torsional>
                <ode/>
              </torsional>
            </friction>
            <contact>
              <ode>
                <soft_cfm>0</soft_cfm>
                <soft_erp>0.2</soft_erp>
                <kp>100000</kp>
                <kd>1</kd>
                <max_vel>0.01</max_vel>
                <min_depth>0.001</min_depth>
              </ode>
            </contact>
            <bounce/>
          </surface>
          <max_contacts>10</max_contacts>
        </collision>
        <visual name='wheel_left_visual'>
          <pose>0 0.144 0.023 0 -0 0</pose>
          <geometry>
            <mesh>
              <uri>model://turtlebot3_common/meshes/tire.dae</uri>
              <scale>0.001 0.001 0.001</scale>
            </mesh>
          </geometry>
        </visual>
        <self_collide>0</self_collide>
        <enable_wind>0</enable_wind>
        <kinematic>0</kinematic>
      </link>
      <link name='wheel_right_link'>
        <inertial>
          <pose>0 -0.144 0.023 -1.57 0 0</pose>
          <inertia>
            <ixx>1.11756e-05</ixx>
            <ixy>-4.23698e-11</ixy>
            <ixz>-5.93817e-09</ixz>
            <iyy>1.11924e-05</iyy>
            <iyz>-1.44001e-11</iyz>
            <izz>2.07126e-05</izz>
          </inertia>
          <mass>0.1</mass>
        </inertial>
        <collision name='wheel_right_collision'>
          <pose>0 -0.144 0.023 -1.57 0 0</pose>
          <geometry>
            <cylinder>
              <radius>0.033</radius>
              <length>0.018</length>
            </cylinder>
          </geometry>
          <surface>
            <friction>
              <ode>
                <mu>100000</mu>
                <mu2>100000</mu2>
                <fdir1>0 0 0</fdir1>
                <slip1>0</slip1>
                <slip2>0</slip2>
              </ode>
              <torsional>
                <ode/>
              </torsional>
            </friction>
            <contact>
              <ode>
                <soft_cfm>0</soft_cfm>
                <soft_erp>0.2</soft_erp>
                <kp>100000</kp>
                <kd>1</kd>
                <max_vel>0.01</max_vel>
                <min_depth>0.001</min_depth>
              </ode>
            </contact>
            <bounce/>
          </surface>
          <max_contacts>10</max_contacts>
        </collision>
        <visual name='wheel_right_visual'>
          <pose>0 -0.144 0.023 0 -0 0</pose>
          <geometry>
            <mesh>
              <uri>model://turtlebot3_common/meshes/tire.dae</uri>
              <scale>0.001 0.001 0.001</scale>
            </mesh>
          </geometry>
        </visual>
        <self_collide>0</self_collide>
        <enable_wind>0</enable_wind>
        <kinematic>0</kinematic>
      </link>
      <link name='caster_back_right_link'>
        <pose>-0.177 -0.064 -0.004 -1.57 0 0</pose>
        <inertial>
          <mass>0.001</mass>
          <inertia>
            <ixx>1e-05</ixx>
            <ixy>0</ixy>
            <ixz>0</ixz>
            <iyy>1e-05</iyy>
            <iyz>0</iyz>
            <izz>1e-05</izz>
          </inertia>
          <pose>0 0 0 0 -0 0</pose>
        </inertial>
        <collision name='collision'>
          <geometry>
            <sphere>
              <radius>0.005</radius>
            </sphere>
          </geometry>
          <surface>
            <contact>
              <ode>
                <soft_cfm>0</soft_cfm>
                <soft_erp>0.2</soft_erp>
                <kp>100000</kp>
                <kd>1</kd>
                <max_vel>0.01</max_vel>
                <min_depth>0.001</min_depth>
              </ode>
            </contact>
            <bounce/>
            <friction>
              <torsional>
                <ode/>
              </torsional>
              <ode/>
            </friction>
          </surface>
          <max_contacts>10</max_contacts>
        </collision>
        <self_collide>0</self_collide>
        <enable_wind>0</enable_wind>
        <kinematic>0</kinematic>
      </link>
      <link name='caster_back_left_link'>
        <pose>-0.177 0.064 -0.004 -1.57 0 0</pose>
        <inertial>
          <mass>0.001</mass>
          <inertia>
            <ixx>1e-05</ixx>
            <ixy>0</ixy>
            <ixz>0</ixz>
            <iyy>1e-05</iyy>
            <iyz>0</iyz>
            <izz>1e-05</izz>
          </inertia>
          <pose>0 0 0 0 -0 0</pose>
        </inertial>
        <collision name='collision'>
          <geometry>
            <sphere>
              <radius>0.005</radius>
            </sphere>
          </geometry>
          <surface>
            <contact>
              <ode>
                <soft_cfm>0</soft_cfm>
                <soft_erp>0.2</soft_erp>
                <kp>100000</kp>
                <kd>1</kd>
                <max_vel>0.01</max_vel>
                <min_depth>0.001</min_depth>
              </ode>
            </contact>
            <bounce/>
            <friction>
              <torsional>
                <ode/>
              </torsional>
              <ode/>
            </friction>
          </surface>
          <max_contacts>10</max_contacts>
        </collision>
        <self_collide>0</self_collide>
        <enable_wind>0</enable_wind>
        <kinematic>0</kinematic>
      </link>
      <link name='camera_link'>
        <self_collide>0</self_collide>
        <inertial>
          <pose>0 0 0 0 -0 0</pose>
          <inertia>
            <ixx>1</ixx>
            <ixy>0</ixy>
            <ixz>0</ixz>
            <iyy>1</iyy>
            <iyz>0</iyz>
            <izz>1</izz>
          </inertia>
          <mass>1</mass>
        </inertial>
        <enable_wind>0</enable_wind>
        <kinematic>0</kinematic>
      </link>
      <link name='camera_rgb_frame'>
        <inertial>
          <pose>0.069 -0.047 0.107 0 -0 0</pose>
          <inertia>
            <ixx>0.001</ixx>
            <ixy>0</ixy>
            <ixz>0</ixz>
            <iyy>0.001</iyy>
            <iyz>0</iyz>
            <izz>0.001</izz>
          </inertia>
          <mass>0.035</mass>
        </inertial>
        <pose>0.069 -0.047 0.107 0 -0 0</pose>
        <sensor name='camera' type='depth'>
          <always_on>1</always_on>
          <visualize>1</visualize>
          <update_rate>30</update_rate>
          <camera name='intel_realsense_r200'>
            <horizontal_fov>1.02974</horizontal_fov>
            <image>
              <width>1920</width>
              <height>1080</height>
              <format>R8G8B8</format>
            </image>
            <clip>
              <near>0.02</near>
              <far>300</far>
            </clip>
            <noise>
              <type>gaussian</type>
              <mean>0</mean>
              <stddev>0.007</stddev>
            </noise>
          </camera>
          <plugin name='camera_driver' filename='libgazebo_ros_camera.so'>
            <ros>
              <namespace>Pursuer</namespace>
            </ros>
          </plugin>
        </sensor>
        <self_collide>0</self_collide>
        <enable_wind>0</enable_wind>
        <kinematic>0</kinematic>
      </link>
      <joint name='base_joint' type='fixed'>
        <parent>base_footprint</parent>
        <child>base_link</child>
        <pose>0 0 0.01 0 -0 0</pose>
      </joint>
      <joint name='wheel_left_joint' type='revolute'>
        <parent>base_link</parent>
        <child>wheel_left_link</child>
        <pose>0 0.144 0.023 -1.57 0 0</pose>
        <axis>
          <xyz>0 0 1</xyz>
          <limit>
            <lower>-1e+16</lower>
            <upper>1e+16</upper>
          </limit>
          <dynamics>
            <spring_reference>0</spring_reference>
            <spring_stiffness>0</spring_stiffness>
          </dynamics>
        </axis>
      </joint>
      <joint name='wheel_right_joint' type='revolute'>
        <parent>base_link</parent>
        <child>wheel_right_link</child>
        <pose>0 -0.144 0.023 -1.57 0 0</pose>
        <axis>
          <xyz>0 0 1</xyz>
          <limit>
            <lower>-1e+16</lower>
            <upper>1e+16</upper>
          </limit>
          <dynamics>
            <spring_reference>0</spring_reference>
            <spring_stiffness>0</spring_stiffness>
          </dynamics>
        </axis>
      </joint>
      <joint name='caster_back_right_joint' type='ball'>
        <parent>base_link</parent>
        <child>caster_back_right_link</child>
      </joint>
      <joint name='caster_back_left_joint' type='ball'>
        <parent>base_link</parent>
        <child>caster_back_left_link</child>
      </joint>
      <joint name='imu_joint' type='fixed'>
        <parent>base_link</parent>
        <child>imu_link</child>
        <pose>-0.032 0 0.068 0 -0 0</pose>
        <axis>
          <xyz>0 0 1</xyz>
          <limit>
            <lower>-1e+16</lower>
            <upper>1e+16</upper>
          </limit>
        </axis>
      </joint>
      <joint name='lidar_joint' type='fixed'>
        <parent>base_link</parent>
        <child>base_scan</child>
        <pose>-0.064 0 0.121 0 -0 0</pose>
        <axis>
          <xyz>0 0 1</xyz>
          <limit>
            <lower>-1e+16</lower>
            <upper>1e+16</upper>
          </limit>
        </axis>
      </joint>
      <joint name='camera_joint' type='fixed'>
        <parent>base_link</parent>
        <child>camera_link</child>
        <pose>0.064 -0.065 0.094 0 -0 0</pose>
        <axis>
          <xyz>0 0 1</xyz>
          <limit>
            <lower>-1e+16</lower>
            <upper>1e+16</upper>
          </limit>
        </axis>
      </joint>
      <joint name='camera_rgb_joint' type='fixed'>
        <parent>camera_link</parent>
        <child>camera_rgb_frame</child>
        <pose>0.005 0.018 0.013 0 -0 0</pose>
        <axis>
          <xyz>0 0 1</xyz>
          <limit>
            <lower>-1e+16</lower>
            <upper>1e+16</upper>
          </limit>
        </axis>
      </joint>
      <plugin name='turtlebot3_diff_drive' filename='libgazebo_ros_diff_drive.so'>
        <ros>
          <namespace>Pursuer</namespace>
        </ros>
        <update_rate>30</update_rate>
        <left_joint>wheel_left_joint</left_joint>
        <right_joint>wheel_right_joint</right_joint>
        <wheel_separation>0.287</wheel_separation>
        <wheel_diameter>0.066</wheel_diameter>
        <max_wheel_torque>20</max_wheel_torque>
        <max_wheel_acceleration>1.0</max_wheel_acceleration>
        <command_topic>cmd_vel</command_topic>
        <publish_odom>1</publish_odom>
        <publish_odom_tf>1</publish_odom_tf>
        <publish_wheel_tf>0</publish_wheel_tf>
        <odometry_topic>odom</odometry_topic>
        <odometry_frame>odom</odometry_frame>
        <robot_base_frame>base_footprint</robot_base_frame>
      </plugin>
      <plugin name='turtlebot3_joint_state' filename='libgazebo_ros_joint_state_publisher.so'>
        <ros>
          <remapping>~/out:=joint_states</remapping>
          <namespace>Pursuer</namespace>
        </ros>
        <update_rate>30</update_rate>
        <joint_name>wheel_left_joint</joint_name>
        <joint_name>wheel_right_joint</joint_name>
      </plugin>
    </model>
    <model name='Evader'>
      <pose>12.5 6.5 0.01 0 -0 3.14</pose>
      <link name='base_footprint'>
        <self_collide>0</self_collide>
        <inertial>
          <pose>0 0 0 0 -0 0</pose>
          <inertia>
            <ixx>1</ixx>
            <ixy>0</ixy>
            <ixz>0</ixz>
            <iyy>1</iyy>
            <iyz>0</iyz>
            <izz>1</izz>
          </inertia>
          <mass>1</mass>
        </inertial>
        <enable_wind>0</enable_wind>
        <kinematic>0</kinematic>
      </link>
      <link name='base_link'>
        <inertial>
          <pose>-0.064 0 0.048 0 -0 0</pose>
          <inertia>
            <ixx>0.0421114</ixx>
            <ixy>0</ixy>
            <ixz>0</ixz>
            <iyy>0.0421114</iyy>
            <iyz>0</iyz>
            <izz>0.0752549</izz>
          </inertia>
          <mass>1.37291</mass>
        </inertial>
        <collision name='base_collision'>
          <pose>-0.064 0 0.048 0 -0 0</pose>
          <geometry>
            <box>
              <size>0.265 0.265 0.089</size>
            </box>
          </geometry>
          <max_contacts>10</max_contacts>
          <surface>
            <contact>
              <ode/>
            </contact>
            <bounce/>
            <friction>
              <torsional>
                <ode/>
              </torsional>
              <ode/>
            </friction>
          </surface>
        </collision>
        <visual name='base_visual'>
          <pose>-0.064 0 0 0 -0 0</pose>
          <geometry>
            <mesh>
              <uri>model://turtlebot3_common/meshes/waffle_base.dae</uri>
              <scale>0.001 0.001 0.001</scale>
            </mesh>
          </geometry>
          <material>
            <ambient>1 0 0 1</ambient>
            <diffuse>1 0 0 1</diffuse>
            <specular>0.1 0.1 0.1 1</specular>
          </material>
        </visual>
        <self_collide>0</self_collide>
        <enable_wind>0</enable_wind>
        <kinematic>0</kinematic>
      </link>
      <link name='imu_link'>
        <sensor name='tb3_imu' type='imu'>
          <always_on>1</always_on>
          <update_rate>200</update_rate>
          <imu>
            <angular_velocity>
              <x>
                <noise type='gaussian'>
                  <mean>0</mean>
                  <stddev>0.0002</stddev>
                </noise>
              </x>
              <y>
                <noise type='gaussian'>
                  <mean>0</mean>
                  <stddev>0.0002</stddev>
                </noise>
              </y>
              <z>
                <noise type='gaussian'>
                  <mean>0</mean>
                  <stddev>0.0002</stddev>
                </noise>
              </z>
            </angular_velocity>
            <linear_acceleration>
              <x>
                <noise type='gaussian'>
                  <mean>0</mean>
                  <stddev>0.017</stddev>
                </noise>
              </x>
              <y>
                <noise type='gaussian'>
                  <mean>0</mean>
                  <stddev>0.017</stddev>
                </noise>
              </y>
              <z>
                <noise type='gaussian'>
                  <mean>0</mean>
                  <stddev>0.017</stddev>
                </noise>
              </z>
            </linear_acceleration>
            <angular_velocity/>
            <linear_acceleration/>
          </imu>
          <plugin name='turtlebot3_imu' filename='libgazebo_ros_imu_sensor.so'>
            <ros>
              <remapping>~/out:=imu</remapping>
              <namespace>Evader</namespace>
            </ros>
          </plugin>
        </sensor>
        <self_collide>0</self_collide>
        <inertial>
          <pose>0 0 0 0 -0 0</pose>
          <inertia>
            <ixx>1</ixx>
            <ixy>0</ixy>
            <ixz>0</ixz>
            <iyy>1</iyy>
            <iyz>0</iyz>
            <izz>1</izz>
          </inertia>
          <mass>1</mass>
        </inertial>
        <enable_wind>0</enable_wind>
        <kinematic>0</kinematic>
      </link>
      <link name='base_scan'>
        <inertial>
          <pose>-0.052 0 0.111 0 -0 0</pose>
          <inertia>
            <ixx>0.001</ixx>
            <ixy>0</ixy>
            <ixz>0</ixz>
            <iyy>0.001</iyy>
            <iyz>0</iyz>
            <izz>0.001</izz>
          </inertia>
          <mass>0.114</mass>
        </inertial>
        <collision name='lidar_sensor_collision'>
          <pose>-0.052 0 0.111 0 -0 0</pose>
          <geometry>
            <cylinder>
              <radius>0.0508</radius>
              <length>0.055</length>
            </cylinder>
          </geometry>
          <max_contacts>10</max_contacts>
          <surface>
            <contact>
              <ode/>
            </contact>
            <bounce/>
            <friction>
              <torsional>
                <ode/>
              </torsional>
              <ode/>
            </friction>
          </surface>
        </collision>
        <visual name='lidar_sensor_visual'>
          <pose>-0.064 0 0.121 0 -0 0</pose>
          <geometry>
            <mesh>
              <uri>model://turtlebot3_common/meshes/lds.dae</uri>
              <scale>0.001 0.001 0.001</scale>
            </mesh>
          </geometry>
        </visual>
        <sensor name='hls_lfcd_lds' type='ray'>
          <always_on>1</always_on>
          <visualize>1</visualize>
          <pose>-0.064 0 0.121 0 -0 0</pose>
          <update_rate>5</update_rate>
          <ray>
            <scan>
              <horizontal>
                <samples>360</samples>
                <resolution>1</resolution>
                <min_angle>0</min_angle>
                <max_angle>6.28</max_angle>
              </horizontal>
              <vertical>
                <samples>1</samples>
                <min_angle>0</min_angle>
                <max_angle>0</max_angle>
              </vertical>
            </scan>
            <range>
              <min>0.12</min>
              <max>3.5</max>
              <resolution>0.015</resolution>
            </range>
            <noise>
              <type>gaussian</type>
              <mean>0</mean>
              <stddev>0.01</stddev>
            </noise>
          </ray>
          <plugin name='turtlebot3_laserscan' filename='libgazebo_ros_ray_sensor.so'>
            <ros>
              <remapping>~/out:=scan</remapping>
              <namespace>Evader</namespace>
            </ros>
            <output_type>sensor_msgs/LaserScan</output_type>
            <frame_name>base_scan</frame_name>
          </plugin>
        </sensor>
        <self_collide>0</self_collide>
        <enable_wind>0</enable_wind>
        <kinematic>0</kinematic>
      </link>
      <link name='wheel_left_link'>
        <inertial>
          <pose>0 0.144 0.023 -1.57 0 0</pose>
          <inertia>
            <ixx>1.11756e-05</ixx>
            <ixy>-4.23698e-11</ixy>
            <ixz>-5.93817e-09</ixz>
            <iyy>1.11924e-05</iyy>
            <iyz>-1.44001e-11</iyz>
            <izz>2.07126e-05</izz>
          </inertia>
          <mass>0.1</mass>
        </inertial>
        <collision name='wheel_left_collision'>
          <pose>0 0.144 0.023 -1.57 0 0</pose>
          <geometry>
            <cylinder>
              <radius>0.033</radius>
              <length>0.018</length>
            </cylinder>
          </geometry>
          <surface>
            <friction>
              <ode>
                <mu>100000</mu>
                <mu2>100000</mu2>
                <fdir1>0 0 0</fdir1>
                <slip1>0</slip1>
                <slip2>0</slip2>
              </ode>
              <torsional>
                <ode/>
              </torsional>
            </friction>
            <contact>
              <ode>
                <soft_cfm>0</soft_cfm>
                <soft_erp>0.2</soft_erp>
                <kp>100000</kp>
                <kd>1</kd>
                <max_vel>0.01</max_vel>
                <min_depth>0.001</min_depth>
              </ode>
            </contact>
            <bounce/>
          </surface>
          <max_contacts>10</max_contacts>
        </collision>
        <visual name='wheel_left_visual'>
          <pose>0 0.144 0.023 0 -0 0</pose>
          <geometry>
            <mesh>
              <uri>model://turtlebot3_common/meshes/tire.dae</uri>
              <scale>0.001 0.001 0.001</scale>
            </mesh>
          </geometry>
        </visual>
        <self_collide>0</self_collide>
        <enable_wind>0</enable_wind>
        <kinematic>0</kinematic>
      </link>
      <link name='wheel_right_link'>
        <inertial>
          <pose>0 -0.144 0.023 -1.57 0 0</pose>
          <inertia>
            <ixx>1.11756e-05</ixx>
            <ixy>-4.23698e-11</ixy>
            <ixz>-5.93817e-09</ixz>
            <iyy>1.11924e-05</iyy>
            <iyz>-1.44001e-11</iyz>
            <izz>2.07126e-05</izz>
          </inertia>
          <mass>0.1</mass>
        </inertial>
        <collision name='wheel_right_collision'>
          <pose>0 -0.144 0.023 -1.57 0 0</pose>
          <geometry>
            <cylinder>
              <radius>0.033</radius>
              <length>0.018</length>
            </cylinder>
          </geometry>
          <surface>
            <friction>
              <ode>
                <mu>100000</mu>
                <mu2>100000</mu2>
                <fdir1>0 0 0</fdir1>
                <slip1>0</slip1>
                <slip2>0</slip2>
              </ode>
              <torsional>
                <ode/>
              </torsional>
            </friction>
            <contact>
              <ode>
                <soft_cfm>0</soft_cfm>
                <soft_erp>0.2</soft_erp>
                <kp>100000</kp>
                <kd>1</kd>
                <max_vel>0.01</max_vel>
                <min_depth>0.001</min_depth>
              </ode>
            </contact>
            <bounce/>
          </surface>
          <max_contacts>10</max_contacts>
        </collision>
        <visual name='wheel_right_visual'>
          <pose>0 -0.144 0.023 0 -0 0</pose>
          <geometry>
            <mesh>
              <uri>model://turtlebot3_common/meshes/tire.dae</uri>
              <scale>0.001 0.001 0.001</scale>
            </mesh>
          </geometry>
        </visual>
        <self_collide>0</self_collide>
        <enable_wind>0</enable_wind>
        <kinematic>0</kinematic>
      </link>
      <link name='caster_back_right_link'>
        <pose>-0.177 -0.064 -0.004 -1.57 0 0</pose>
        <inertial>
          <mass>0.001</mass>
          <inertia>
            <ixx>1e-05</ixx>
            <ixy>0</ixy>
            <ixz>0</ixz>
            <iyy>1e-05</iyy>
            <iyz>0</iyz>
            <izz>1e-05</izz>
          </inertia>
          <pose>0 0 0 0 -0 0</pose>
        </inertial>
        <collision name='collision'>
          <geometry>
            <sphere>
              <radius>0.005</radius>
            </sphere>
          </geometry>
          <surface>
            <contact>
              <ode>
                <soft_cfm>0</soft_cfm>
                <soft_erp>0.2</soft_erp>
                <kp>100000</kp>
                <kd>1</kd>
                <max_vel>0.01</max_vel>
                <min_depth>0.001</min_depth>
              </ode>
            </contact>
            <bounce/>
            <friction>
              <torsional>
                <ode/>
              </torsional>
              <ode/>
            </friction>
          </surface>
          <max_contacts>10</max_contacts>
        </collision>
        <self_collide>0</self_collide>
        <enable_wind>0</enable_wind>
        <kinematic>0</kinematic>
      </link>
      <link name='caster_back_left_link'>
        <pose>-0.177 0.064 -0.004 -1.57 0 0</pose>
        <inertial>
          <mass>0.001</mass>
          <inertia>
            <ixx>1e-05</ixx>
            <ixy>0</ixy>
            <ixz>0</ixz>
            <iyy>1e-05</iyy>
            <iyz>0</iyz>
            <izz>1e-05</izz>
          </inertia>
          <pose>0 0 0 0 -0 0</pose>
        </inertial>
        <collision name='collision'>
          <geometry>
            <sphere>
              <radius>0.005</radius>
            </sphere>
          </geometry>
          <surface>
            <contact>
              <ode>
                <soft_cfm>0</soft_cfm>
                <soft_erp>0.2</soft_erp>
                <kp>100000</kp>
                <kd>1</kd>
                <max_vel>0.01</max_vel>
                <min_depth>0.001</min_depth>
              </ode>
            </contact>
            <bounce/>
            <friction>
              <torsional>
                <ode/>
              </torsional>
              <ode/>
            </friction>
          </surface>
          <max_contacts>10</max_contacts>
        </collision>
        <self_collide>0</self_collide>
        <enable_wind>0</enable_wind>
        <kinematic>0</kinematic>
      </link>
      <link name='camera_link'>
        <self_collide>0</self_collide>
        <inertial>
          <pose>0 0 0 0 -0 0</pose>
          <inertia>
            <ixx>1</ixx>
            <ixy>0</ixy>
            <ixz>0</ixz>
            <iyy>1</iyy>
            <iyz>0</iyz>
            <izz>1</izz>
          </inertia>
          <mass>1</mass>
        </inertial>
        <enable_wind>0</enable_wind>
        <kinematic>0</kinematic>
      </link>
      <link name='camera_rgb_frame'>
        <inertial>
          <pose>0.069 -0.047 0.107 0 -0 0</pose>
          <inertia>
            <ixx>0.001</ixx>
            <ixy>0</ixy>
            <ixz>0</ixz>
            <iyy>0.001</iyy>
            <iyz>0</iyz>
            <izz>0.001</izz>
          </inertia>
          <mass>0.035</mass>
        </inertial>
        <pose>0.069 -0.047 0.107 0 -0 0</pose>
        <sensor name='camera' type='camera'>
          <always_on>1</always_on>
          <visualize>1</visualize>
          <update_rate>30</update_rate>
          <camera name='intel_realsense_r200'>
            <horizontal_fov>1.02974</horizontal_fov>
            <image>
              <width>1920</width>
              <height>1080</height>
              <format>R8G8B8</format>
            </image>
            <clip>
              <near>0.02</near>
              <far>300</far>
            </clip>
            <noise>
              <type>gaussian</type>
              <mean>0</mean>
              <stddev>0.007</stddev>
            </noise>
          </camera>
          <plugin name='camera_driver' filename='libgazebo_ros_camera.so'>
            <ros>
              <namespace>Evader</namespace>
            </ros>
          </plugin>
        </sensor>
        <self_collide>0</self_collide>
        <enable_wind>0</enable_wind>
        <kinematic>0</kinematic>
      </link>
      <joint name='base_joint' type='fixed'>
        <parent>base_footprint</parent>
        <child>base_link</child>
        <pose>0 0 0.01 0 -0 0</pose>
      </joint>
      <joint name='wheel_left_joint' type='revolute'>
        <parent>base_link</parent>
        <child>wheel_left_link</child>
        <pose>0 0.144 0.023 -1.57 0 0</pose>
        <axis>
          <xyz>0 0 1</xyz>
          <limit>
            <lower>-1e+16</lower>
            <upper>1e+16</upper>
          </limit>
          <dynamics>
            <spring_reference>0</spring_reference>
            <spring_stiffness>0</spring_stiffness>
          </dynamics>
        </axis>
      </joint>
      <joint name='wheel_right_joint' type='revolute'>
        <parent>base_link</parent>
        <child>wheel_right_link</child>
        <pose>0 -0.144 0.023 -1.57 0 0</pose>
        <axis>
          <xyz>0 0 1</xyz>
          <limit>
            <lower>-1e+16</lower>
            <upper>1e+16</upper>
          </limit>
          <dynamics>
            <spring_reference>0</spring_reference>
            <spring_stiffness>0</spring_stiffness>
          </dynamics>
        </axis>
      </joint>
      <joint name='caster_back_right_joint' type='ball'>
        <parent>base_link</parent>
        <child>caster_back_right_link</child>
      </joint>
      <joint name='caster_back_left_joint' type='ball'>
        <parent>base_link</parent>
        <child>caster_back_left_link</child>
      </joint>
      <joint name='imu_joint' type='fixed'>
        <parent>base_link</parent>
        <child>imu_link</child>
        <pose>-0.032 0 0.068 0 -0 0</pose>
        <axis>
          <xyz>0 0 1</xyz>
          <limit>
            <lower>-1e+16</lower>
            <upper>1e+16</upper>
          </limit>
        </axis>
      </joint>
      <joint name='lidar_joint' type='fixed'>
        <parent>base_link</parent>
        <child>base_scan</child>
        <pose>-0.064 0 0.121 0 -0 0</pose>
        <axis>
          <xyz>0 0 1</xyz>
          <limit>
            <lower>-1e+16</lower>
            <upper>1e+16</upper>
          </limit>
        </axis>
      </joint>
      <joint name='camera_joint' type='fixed'>
        <parent>base_link</parent>
        <child>camera_link</child>
        <pose>0.064 -0.065 0.094 0 -0 0</pose>
        <axis>
          <xyz>0 0 1</xyz>
          <limit>
            <lower>-1e+16</lower>
            <upper>1e+16</upper>
          </limit>
        </axis>
      </joint>
      <joint name='camera_rgb_joint' type='fixed'>
        <parent>camera_link</parent>
        <child>camera_rgb_frame</child>
        <pose>0.005 0.018 0.013 0 -0 0</pose>
        <axis>
          <xyz>0 0 1</xyz>
          <limit>
            <lower>-1e+16</lower>
            <upper>1e+16</upper>
          </limit>
        </axis>
      </joint>
      <plugin name='turtlebot3_diff_drive' filename='libgazebo_ros_diff_drive.so'>
        <ros>
          <namespace>Evader</namespace>
        </ros>
        <update_rate>30</update_rate>
        <left_joint>wheel_left_joint</left_joint>
        <right_joint>wheel_right_joint</right_joint>
        <wheel_separation>0.287</wheel_separation>
        <wheel_diameter>0.066</wheel_diameter>
        <max_wheel_torque>20</max_wheel_torque>
        <max_wheel_acceleration>1.0</max_wheel_acceleration>
        <command_topic>cmd_vel</command_topic>
        <publish_odom>1</publish_odom>
        <publish_odom_tf>1</publish_odom_tf>
        <publish_wheel_tf>0</publish_wheel_tf>
        <odometry_topic>odom</odometry_topic>
        <odometry_frame>odom</odometry_frame>
        <robot_base_frame>base_footprint</robot_base_frame>
      </plugin>
      <plugin name='turtlebot3_joint_state' filename='libgazebo_ros_joint_state_publisher.so'>
        <ros>
          <remapping>~/out:=joint_states</remapping>
          <namespace>Evader</namespace>
        </ros>
        <update_rate>30</update_rate>
        <joint_name>wheel_left_joint</joint_name>
        <joint_name>wheel_right_joint</joint_name>
      </plugin>
    </model>
  </world>
</sdf>
